Workbook

Sheet Walmart_Sales_raw_data
A1: Store | B1: Date | C1: Weekly_Sales | D1: Holiday_Flag | E1: Temperature | F1: Fuel_Price | G1: CPI | H1: Unemployment | I1: Column1
A2: 1 | B2: 40214 | C2: 1643690.9 | D2: 0 | E2: 42.31 | F2: 2.572 | G2: 211.09636 | H2: 8.106 | I2: =COUNTIF(A2:A6437,#REF!="High") -> 0
A3: 1 | B3: 40221 | C3: 1641957.4 | D3: 1 | E3: 38.51 | F3: 2.548 | G3: 211.24217 | H3: 8.106
A4: 1 | B4: 40228 | C4: 1611968.2 | D4: 0 | E4: 39.93 | F4: 2.514 | G4: 211.28914 | H4: 8.106
A5: 1 | B5: 40235 | C5: 1409727.6 | D5: 0 | E5: 46.63 | F5: 2.561 | G5: 211.31964 | H5: 8.106
A6: 1 | B6: 40242 | C6: 1554806.7 | D6: 0 | E6: 46.5 | F6: 2.625 | G6: 211.35014 | H6: 8.106
A7: 1 | B7: 40249 | C7: 1439541.6 | D7: 0 | E7: 57.79 | F7: 2.667 | G7: 211.38064 | H7: 8.106
A8: 1 | B8: 40256 | C8: 1472515.8 | D8: 0 | E8: 54.58 | F8: 2.72 | G8: 211.21563 | H8: 8.106
A9: 1 | B9: 40263 | C9: 1404429.9 | D9: 0 | E9: 51.45 | F9: 2.732 | G9: 211.01804 | H9: 8.106
A10: 1 | B10: 40270 | C10: 1594968.3 | D10: 0 | E10: 62.27 | F10: 2.719 | G10: 210.82045 | H10: 7.808
A11: 1 | B11: 40277 | C11: 1545418.5 | D11: 0 | E11: 65.86 | F11: 2.77 | G11: 210.62286 | H11: 7.808
A12: 1 | B12: 40284 | C12: 1466058.3 | D12: 0 | E12: 66.32 | F12: 2.808 | G12: 210.4887 | H12: 7.808
A13: 1 | B13: 40291 | C13: 1391256.1 | D13: 0 | E13: 64.84 | F13: 2.795 | G13: 210.43912 | H13: 7.808
A14: 1 | B14: 40298 | C14: 1425100.7 | D14: 0 | E14: 67.41 | F14: 2.78 | G14: 210.38955 | H14: 7.808
... A6436: 45 | B6436: 41208 | C6436: 760281.43 | D6436: 0 | E6436: 58.85 | F6436: 3.882 | G6436: 192.3089 | H6436: 8.667
C6437: =AVERAGE(C1:C6436) -> 1046964.9

Sheet Average_weeklysales_per_store
A1: SORTED FROM HIGHEST TO LOWEST AVERAGE WEEKLY SALES
A2: Store | B2: Average of Weekly_Sales
A3: 20 | B3: 2107676.9
A4: 4 | B4: 2094713
A5: 14 | B5: 2020978.4
A6: 13 | B6: 2003620.3
A7: 2 | B7: 1925751.3
A8: 10 | B8: 1899424.6
A9: 27 | B9: 1775216.2
A10: 6 | B10: 1564728.2
A11: 1 | B11: 1555264.4
A12: 39 | B12: 1450668.1
A13: 19 | B13: 1444999
A14: 31 | B14: 1395901.4
... A47: 33 | B47: 259861.69
A48: Grand Total | B48: 1046964.9

Sheet Sum_of_weeklysales_per_store
A1: SORTED FROM HIGHEST TO LOWEST WEEKLY SALES PER STORE | E1: In this section, the sum of weekly sales per store is evaluated in descending order
A2: Store | B2: Sum of Weekly_Sales
A3: 20 | B3: 3.0139779e+08
A4: 4 | B4: 2.9954395e+08
A5: 14 | B5: 2.8899991e+08
A6: 13 | B6: 2.865177e+08
A7: 2 | B7: 2.7538244e+08
A8: 10 | B8: 2.7161771e+08
A9: 27 | B9: 2.5385592e+08
A10: 6 | B10: 2.2375613e+08
A11: 1 | B11: 2.2240281e+08
A12: 39 | B12: 2.0744554e+08
A13: 19 | B13: 2.0663486e+08
A14: 31 | B14: 1.9961391e+08
... A47: 33 | B47: 37160222
A48: Grand Total | B48: 6.737219e+09

Sheet Store_performance
A1: Store | B1: Weekly performance (in descending order) | D1: IMPORTANT TO NOTE: In this section, Stores were categorized in decending order into "High weekly sales" and "Low weekly sales" by the following metric: Average weekly sales per store >=Overall average weekly sales = High weekly sales and vice versa
A2: =Average_weeklysales_per_store!A3 -> 20 | B2: =IF(Average_weeklysales_per_store!B3>=Average_weeklysales_per_store!$B$48,"High weekly sales","Low weekly sales") -> High weekly sales
A3: =Average_weeklysales_per_store!A4 -> 4 | B3: =IF(Average_weeklysales_per_store!B4>=Average_weeklysales_per_store!$B$48,"High weekly sales","Low weekly sales") -> High weekly sales
A4: =Average_weeklysales_per_store!A5 -> 14 | B4: =IF(Average_weeklysales_per_store!B5>=Average_weeklysales_per_store!$B$48,"High weekly sales","Low weekly sales") -> High weekly sales
A5: =Average_weeklysales_per_store!A6 -> 13 | B5: =IF(Average_weeklysales_per_store!B6>=Average_weeklysales_per_store!$B$48,"High weekly sales","Low weekly sales") -> High weekly sales
A6: =Average_weeklysales_per_store!A7 -> 2 | B6: =IF(Average_weeklysales_per_store!B7>=Average_weeklysales_per_store!$B$48,"High weekly sales","Low weekly sales") -> High weekly sales | D6: List of Stores with High weekly sales | F6: List of Stores with Low weekly sales
A7: =Average_weeklysales_per_store!A8 -> 10 | B7: =IF(Average_weeklysales_per_store!B8>=Average_weeklysales_per_store!$B$48,"High weekly sales","Low weekly sales") -> High weekly sales
A8: =Average_weeklysales_per_store!A9 -> 27 | B8: =IF(Average_weeklysales_per_store!B9>=Average_weeklysales_per_store!$B$48,"High weekly sales","Low weekly sales") -> High weekly sales
A9: =Average_weeklysales_per_store!A10 -> 6 | B9: =IF(Average_weeklysales_per_store!B10>=Average_weeklysales_per_store!$B$48,"High weekly sales","Low weekly sales") -> High weekly sales
A10: =Average_weeklysales_per_store!A11 -> 1 | B10: =IF(Average_weeklysales_per_store!B11>=Average_weeklysales_per_store!$B$48,"High weekly sales","Low weekly sales") -> High weekly sales
A11: =Average_weeklysales_per_store!A12 -> 39 | B11: =IF(Average_weeklysales_per_store!B12>=Average_weeklysales_per_store!$B$48,"High weekly sales","Low weekly sales") -> High weekly sales
A12: =Average_weeklysales_per_store!A13 -> 19 | B12: =IF(Average_weeklysales_per_store!B13>=Average_weeklysales_per_store!$B$48,"High weekly sales","Low weekly sales") -> High weekly sales
A13: =Average_weeklysales_per_store!A14 -> 31 | B13: =IF(Average_weeklysales_per_store!B14>=Average_weeklysales_per_store!$B$48,"High weekly sales","Low weekly sales") -> High weekly sales
A14: =Average_weeklysales_per_store!A15 -> 23 | B14: =IF(Average_weeklysales_per_store!B15>=Average_weeklysales_per_store!$B$48,"High weekly sales","Low weekly sales") -> High weekly sales
A15: =Average_weeklysales_per_store!A16 -> 24 | B15: =IF(Average_weeklysales_per_store!B16>=Average_weeklysales_per_store!$B$48,"High weekly sales","Low weekly sales") -> High weekly sales
A16: =Average_weeklysales_per_store!A17 -> 11 | B16: =IF(Average_weeklysales_per_store!B17>=Average_weeklysales_per_store!$B$48,"High weekly sales","Low weekly sales") -> High weekly sales
A17: =Average_weeklysales_per_store!A18 -> 28 | B17: =IF(Average_weeklysales_per_store!B18>=Average_weeklysales_per_store!$B$48,"High weekly sales","Low weekly sales") -> High weekly sales
A18: =Average_weeklysales_per_store!A19 -> 41 | B18: =IF(Average_weeklysales_per_store!B19>=Average_weeklysales_per_store!$B$48,"High weekly sales","Low weekly sales") -> High weekly sales
... A46: =Average_weeklysales_per_store!A47 -> 33 | B46: =IF(Average_weeklysales_per_store!B47>=Average_weeklysales_per_store!$B$48,"High weekly sales","Low weekly sales") -> Low weekly sales
F59: {=_xlfn._xlws.FILTER($A$2:$A$46,$B$2:$B$46="High weekly sales")} -> 20 | G59: {=_xlfn._xlws.FILTER($A$2:$A$46,$B$2:$B$46="Low weekly sales")} -> 22 | I59: {=_xlfn._xlws.FILTER(B2:B46,$B$2:$B$46="High weekly sales")} -> High weekly sales | J59: {=_xlfn._xlws.FILTER(B2:B46,$B$2:$B$46="Low weekly sales")} -> Low weekly sales
F60: 4 | G60: 12 | I60: High weekly sales | J60: Low weekly sales
F61: 14 | G61: 26 | I61: High weekly sales | J61: Low weekly sales
F62: 13 | G62: 34 | I62: High weekly sales | J62: Low weekly sales
F63: 2 | G63: 40 | I63: High weekly sales | J63: Low weekly sales
F64: 10 | G64: 35 | I64: High weekly sales | J64: Low weekly sales
F65: 27 | G65: 8 | I65: High weekly sales | J65: Low weekly sales
F66: 6 | G66: 17 | I66: High weekly sales | J66: Low weekly sales
F67: 1 | G67: 45 | I67: High weekly sales | J67: Low weekly sales
F68: 39 | G68: 21 | I68: High weekly sales | J68: Low weekly sales
F69: 19 | G69: 25 | I69: High weekly sales | J69: Low weekly sales
F70: 31 | G70: 43 | I70: High weekly sales | J70: Low weekly sales
F71: 23 | G71: 15 | I71: High weekly sales | J71: Low weekly sales
... F77: 18 | G77: 37 | I77: High weekly sales | J77: Low weekly sales
G78: 30 | J78: Low weekly sales
G79: 3 | I79: =(COUNTA(_xlfn.ANCHORARRAY(I59))) -> 19 | J79: Low weekly sales
G80: 38 | J80: Low weekly sales
E81: Low weekly sales | F81: High weekly sales | G81: 36 | J81: Low weekly sales
E82: =COUNTA(_xlfn.ANCHORARRAY(J59))/(COUNTA(_xlfn.ANCHORARRAY(I59))+COUNTA(_xlfn.ANCHORARRAY(J59)))*360/360 -> 0.57777778 | F82: =(COUNTA(_xlfn.ANCHORARRAY(I59))/(COUNTA(_xlfn.ANCHORARRAY(I59))+COUNTA(_xlfn.ANCHORARRAY(J59)))*360/360) -> 0.42222222 | G82: 5 | J82: Low weekly sales
G83: 44 | J83: Low weekly sales
G84: 33 | J84: Low weekly sales
...

Sheet Consistency_report
A1: =list_of_stores!A1 -> Store | B1: No of weeks with low sales | C1: No of weeks with high sales | F1: In this section, the Performance Consistency of each store in producing High weekly sales(i.e individual weekly sales above the overall average weekly sale across the stores) over the total duration of 143 weeks, is evaluated and stores are appropriately categorized into "Outstanding Consistency", "Consistent", "Fairly consistent" and "Poorly consistent
A2: =list_of_stores!A2 -> 1 | B2: =COUNTIFS(Walmart_Sales_raw_data!A2:A6437,A2,sales_level!C2:C6437,"Low") -> 0 | C2: =COUNTIFS(Walmart_Sales_raw_data!A2:A6437,A2,sales_level!C2:C6437,"High") -> 143
A3: =list_of_stores!A3 -> 2 | B3: =COUNTIFS(Walmart_Sales_raw_data!A3:A6438,A3,sales_level!C3:C6438,"Low") -> 0 | C3: =COUNTIFS(Walmart_Sales_raw_data!A3:A6438,A3,sales_level!C3:C6438,"High") -> 143
A4: =list_of_stores!A5 -> 4 | B4: =COUNTIFS(Walmart_Sales_raw_data!A4:A6439,A4,sales_level!C4:C6439,"Low") -> 0 | C4: =COUNTIFS(Walmart_Sales_raw_data!A4:A6439,A4,sales_level!C4:C6439,"High") -> 143
A5: =list_of_stores!A7 -> 6 | B5: =COUNTIFS(Walmart_Sales_raw_data!A5:A6440,A5,sales_level!C5:C6440,"Low") -> 0 | C5: =COUNTIFS(Walmart_Sales_raw_data!A5:A6440,A5,sales_level!C5:C6440,"High") -> 143
A6: =list_of_stores!A11 -> 10 | B6: =COUNTIFS(Walmart_Sales_raw_data!A6:A6441,A6,sales_level!C6:C6441,"Low") -> 0 | C6: =COUNTIFS(Walmart_Sales_raw_data!A6:A6441,A6,sales_level!C6:C6441,"High") -> 143
A7: =list_of_stores!A12 -> 11 | B7: =COUNTIFS(Walmart_Sales_raw_data!A7:A6442,A7,sales_level!C7:C6442,"Low") -> 0 | C7: =COUNTIFS(Walmart_Sales_raw_data!A7:A6442,A7,sales_level!C7:C6442,"High") -> 143
A8: =list_of_stores!A14 -> 13 | B8: =COUNTIFS(Walmart_Sales_raw_data!A8:A6443,A8,sales_level!C8:C6443,"Low") -> 0 | C8: =COUNTIFS(Walmart_Sales_raw_data!A8:A6443,A8,sales_level!C8:C6443,"High") -> 143 | E8: List of Stores with Outstanding Consistency(all 143 weeks) Click cell below to reveal | H8: List of Consistent stores(less than 143 weeks but greater than 100) Click cell below to reveal | K8: List of fairly Consistent stores(less than 100 weeks but greater than 75) Click cell below to reveal | N8: List of poorly Consistent stores(less than 75) Click cell below to reveal
A9: =list_of_stores!A15 -> 14 | B9: =COUNTIFS(Walmart_Sales_raw_data!A9:A6444,A9,sales_level!C9:C6444,"Low") -> 0 | C9: =COUNTIFS(Walmart_Sales_raw_data!A9:A6444,A9,sales_level!C9:C6444,"High") -> 143
A10: =list_of_stores!A20 -> 19 | B10: =COUNTIFS(Walmart_Sales_raw_data!A10:A6445,A10,sales_level!C10:C6445,"Low") -> 0 | C10: =COUNTIFS(Walmart_Sales_raw_data!A10:A6445,A10,sales_level!C10:C6445,"High") -> 143
A11: =list_of_stores!A21 -> 20 | B11: =COUNTIFS(Walmart_Sales_raw_data!A11:A6446,A11,sales_level!C11:C6446,"Low") -> 0 | C11: =COUNTIFS(Walmart_Sales_raw_data!A11:A6446,A11,sales_level!C11:C6446,"High") -> 143
A12: =list_of_stores!A25 -> 24 | B12: =COUNTIFS(Walmart_Sales_raw_data!A12:A6447,A12,sales_level!C12:C6447,"Low") -> 0 | C12: =COUNTIFS(Walmart_Sales_raw_data!A12:A6447,A12,sales_level!C12:C6447,"High") -> 143 | E12: 1 | H12: 23 | N12: 18
A13: =list_of_stores!A28 -> 27 | B13: =COUNTIFS(Walmart_Sales_raw_data!A13:A6448,A13,sales_level!C13:C6448,"Low") -> 0 | C13: =COUNTIFS(Walmart_Sales_raw_data!A13:A6448,A13,sales_level!C13:C6448,"High") -> 143
A14: =list_of_stores!A29 -> 28 | B14: =COUNTIFS(Walmart_Sales_raw_data!A14:A6449,A14,sales_level!C14:C6449,"Low") -> 0 | C14: =COUNTIFS(Walmart_Sales_raw_data!A14:A6449,A14,sales_level!C14:C6449,"High") -> 143
A15: =list_of_stores!A32 -> 31 | B15: =COUNTIFS(Walmart_Sales_raw_data!A15:A6450,A15,sales_level!C15:C6450,"Low") -> 0 | C15: =COUNTIFS(Walmart_Sales_raw_data!A15:A6450,A15,sales_level!C15:C6450,"High") -> 143
A16: =list_of_stores!A40 -> 39 | B16: =COUNTIFS(Walmart_Sales_raw_data!A16:A6451,A16,sales_level!C16:C6451,"Low") -> 0 | C16: =COUNTIFS(Walmart_Sales_raw_data!A16:A6451,A16,sales_level!C16:C6451,"High") -> 143
A17: =list_of_stores!A24 -> 23 | B17: =COUNTIFS(Walmart_Sales_raw_data!A17:A6452,A17,sales_level!C17:C6452,"Low") -> 4 | C17: =COUNTIFS(Walmart_Sales_raw_data!A17:A6452,A17,sales_level!C17:C6452,"High") -> 139
A18: =list_of_stores!A33 -> 32 | B18: =COUNTIFS(Walmart_Sales_raw_data!A18:A6453,A18,sales_level!C18:C6453,"Low") -> 6 | C18: =COUNTIFS(Walmart_Sales_raw_data!A18:A6453,A18,sales_level!C18:C6453,"High") -> 137
A19: =list_of_stores!A42 -> 41 | B19: =COUNTIFS(Walmart_Sales_raw_data!A19:A6454,A19,sales_level!C19:C6454,"Low") -> 7 | C19: =COUNTIFS(Walmart_Sales_raw_data!A19:A6454,A19,sales_level!C19:C6454,"High") -> 136
A20: =list_of_stores!A19 -> 18 | B20: =COUNTIFS(Walmart_Sales_raw_data!A20:A6455,A20,sales_level!C20:C6455,"Low") -> 57 | C20: =COUNTIFS(Walmart_Sales_raw_data!A20:A6455,A20,sales_level!C20:C6455,"High") -> 86
A21: =list_of_stores!A27 -> 26 | B21: =COUNTIFS(Walmart_Sales_raw_data!A21:A6456,A21,sales_level!C21:C6456,"Low") -> 103 | C21: =COUNTIFS(Walmart_Sales_raw_data!A21:A6456,A21,sales_level!C21:C6456,"High") -> 40
A22: =list_of_stores!A23 -> 22 | B22: =COUNTIFS(Walmart_Sales_raw_data!A22:A6457,A22,sales_level!C22:C6457,"Low") -> 104 | C22: =COUNTIFS(Walmart_Sales_raw_data!A22:A6457,A22,sales_level!C22:C6457,"High") -> 39
A23: =list_of_stores!A13 -> 12 | B23: =COUNTIFS(Walmart_Sales_raw_data!A23:A6458,A23,sales_level!C23:C6458,"Low") -> 106 | C23: =COUNTIFS(Walmart_Sales_raw_data!A23:A6458,A23,sales_level!C23:C6458,"High") -> 37
A24: =list_of_stores!A36 -> 35 | B24: =COUNTIFS(Walmart_Sales_raw_data!A24:A6459,A24,sales_level!C24:C6459,"Low") -> 109 | C24: =COUNTIFS(Walmart_Sales_raw_data!A24:A6459,A24,sales_level!C24:C6459,"High") -> 34
A25: =list_of_stores!A41 -> 40 | B25: =COUNTIFS(Walmart_Sales_raw_data!A25:A6460,A25,sales_level!C25:C6460,"Low") -> 119 | C25: =COUNTIFS(Walmart_Sales_raw_data!A25:A6460,A25,sales_level!C25:C6460,"High") -> 24
A26: =list_of_stores!A18 -> 17 | B26: =COUNTIFS(Walmart_Sales_raw_data!A26:A6461,A26,sales_level!C26:C6461,"Low") -> 129 | C26: =COUNTIFS(Walmart_Sales_raw_data!A26:A6461,A26,sales_level!C26:C6461,"High") -> 14
A27: =list_of_stores!A35 -> 34 | B27: =COUNTIFS(Walmart_Sales_raw_data!A27:A6462,A27,sales_level!C27:C6462,"Low") -> 130 | C27: =COUNTIFS(Walmart_Sales_raw_data!A27:A6462,A27,sales_level!C27:C6462,"High") -> 13
A28: =list_of_stores!A9 -> 8 | B28: =COUNTIFS(Walmart_Sales_raw_data!A28:A6463,A28,sales_level!C28:C6463,"Low") -> 133 | C28: =COUNTIFS(Walmart_Sales_raw_data!A28:A6463,A28,sales_level!C28:C6463,"High") -> 10
A29: =list_of_stores!A46 -> 45 | B29: =COUNTIFS(Walmart_Sales_raw_data!A29:A6464,A29,sales_level!C29:C6464,"Low") -> 137 | C29: =COUNTIFS(Walmart_Sales_raw_data!A29:A6464,A29,sales_level!C29:C6464,"High") -> 6
A30: =list_of_stores!A22 -> 21 | B30: =COUNTIFS(Walmart_Sales_raw_data!A30:A6465,A30,sales_level!C30:C6465,"Low") -> 138 | C30: =COUNTIFS(Walmart_Sales_raw_data!A30:A6465,A30,sales_level!C30:C6465,"High") -> 5
A31: =list_of_stores!A26 -> 25 | B31: =COUNTIFS(Walmart_Sales_raw_data!A31:A6466,A31,sales_level!C31:C6466,"Low") -> 138 | C31: =COUNTIFS(Walmart_Sales_raw_data!A31:A6466,A31,sales_level!C31:C6466,"High") -> 5
A32: =list_of_stores!A16 -> 15 | B32: =COUNTIFS(Walmart_Sales_raw_data!A32:A6467,A32,sales_level!C32:C6467,"Low") -> 139 | C32: =COUNTIFS(Walmart_Sales_raw_data!A32:A6467,A32,sales_level!C32:C6467,"High") -> 4
A33: =list_of_stores!A8 -> 7 | B33: =COUNTIFS(Walmart_Sales_raw_data!A33:A6468,A33,sales_level!C33:C6468,"Low") -> 142 | C33: =COUNTIFS(Walmart_Sales_raw_data!A33:A6468,A33,sales_level!C33:C6468,"High") -> 1
A34: =list_of_stores!A30 -> 29 | B34: =COUNTIFS(Walmart_Sales_raw_data!A34:A6469,A34,sales_level!C34:C6469,"Low") -> 142 | C34: =COUNTIFS(Walmart_Sales_raw_data!A34:A6469,A34,sales_level!C34:C6469,"High") -> 1
A35: =list_of_stores!A4 -> 3 | B35: =COUNTIFS(Walmart_Sales_raw_data!A35:A6470,A35,sales_level!C35:C6470,"Low") -> 143 | C35: =COUNTIFS(Walmart_Sales_raw_data!A35:A6470,A35,sales_level!C35:C6470,"High") -> 0
A36: =list_of_stores!A6 -> 5 | B36: =COUNTIFS(Walmart_Sales_raw_data!A36:A6471,A36,sales_level!C36:C6471,"Low") -> 143 | C36: =COUNTIFS(Walmart_Sales_raw_data!A36:A6471,A36,sales_level!C36:C6471,"High") -> 0
A37: =list_of_stores!A10 -> 9 | B37: =COUNTIFS(Walmart_Sales_raw_data!A37:A6472,A37,sales_level!C37:C6472,"Low") -> 143 | C37: =COUNTIFS(Walmart_Sales_raw_data!A37:A6472,A37,sales_level!C37:C6472,"High") -> 0
A38: =list_of_stores!A17 -> 16 | B38: =COUNTIFS(Walmart_Sales_raw_data!A38:A6473,A38,sales_level!C38:C6473,"Low") -> 143 | C38: =COUNTIFS(Walmart_Sales_raw_data!A38:A6473,A38,sales_level!C38:C6473,"High") -> 0
A39: =list_of_stores!A31 -> 30 | B39: =COUNTIFS(Walmart_Sales_raw_data!A39:A6474,A39,sales_level!C39:C6474,"Low") -> 143 | C39: =COUNTIFS(Walmart_Sales_raw_data!A39:A6474,A39,sales_level!C39:C6474,"High") -> 0
A40: =list_of_stores!A34 -> 33 | B40: =COUNTIFS(Walmart_Sales_raw_data!A40:A6475,A40,sales_level!C40:C6475,"Low") -> 143 | C40: =COUNTIFS(Walmart_Sales_raw_data!A40:A6475,A40,sales_level!C40:C6475,"High") -> 0
...

Sheet Economic_data_correlations
A1: Correlation between sales and Climatic and Economic factors | D1: Inference
F2: Most correlated economic/climatic factor i.e has most impact on weekly sales
A3: Temperature | C3: {=CORREL(Walmart_Sales_raw_data!C2:C6437,Walmart_Sales_raw_data!E2:E6437)} -> -0.063810013 | D3: {=_xlfn.IFS(AND(C3>=-0.19,C3<0),"very weak negative correlation",AND(C3<=-0.2,C3>=-0.39),"weak negative correlation",AND(C3<=-0.4,C3>=-0.59),"moderate negative correlation",AND(C3<=-0.6,C3>=-0.79),"strong negative correlation",AND(C3<=-0.8,C3>=-1),"very strong negative correlation",AND(C3<=0.19,C3>0),"very weak postive correlation",AND(C3>=0.2,C3<=0.39),"weak postive correlation",AND(C3>=0.4,C3<=0.59),"moderate postive correlation",AND(C3>=0.6,C3<=0.79),"strong postive correlation",AND(C3>=0.8,C3<=1),"very weak postive correlation")} -> very weak negative correlation | F3: {=_xlfn.XLOOKUP(MIN(ABS(ABS(C:C)-1)),ABS(ABS(C:C)-1),A:A)} -> unemployment rate
A4: fuel price | C4: {=CORREL(Walmart_Sales_raw_data!C2:C6437,Walmart_Sales_raw_data!F2:F6437)} -> 0.0094637863 | D4: {=_xlfn.IFS(AND(C4>=-0.19,C4<0),"very weak negative correlation",AND(C4<=-0.2,C4>=-0.39),"weak negative correlation",AND(C4<=-0.4,C4>=-0.59),"moderate negative correlation",AND(C4<=-0.6,C4>=-0.79),"strong negative correlation",AND(C4<=-0.8,C4>=-1),"very strong negative correlation",AND(C4<=0.19,C4>0),"very weak postive correlation",AND(C4>=0.2,C4<=0.39),"weak postive correlation",AND(C4>=0.4,C4<=0.59),"moderate postive correlation",AND(C4>=0.6,C4<=0.79),"strong postive correlation",AND(C4>=0.8,C4<=1),"very weak postive correlation")} -> very weak postive correlation | F4: =_xlfn.XLOOKUP(F3,A:A,D:D) -> very weak negative correlation
A5: unemployment rate | C5: {=CORREL(Walmart_Sales_raw_data!C2:C6437,Walmart_Sales_raw_data!H2:H6437)} -> -0.10617609 | D5: {=_xlfn.IFS(AND(C5>=-0.19,C5<0),"very weak negative correlation",AND(C5<=-0.2,C5>=-0.39),"weak negative correlation",AND(C5<=-0.4,C5>=-0.59),"moderate negative correlation",AND(C5<=-0.6,C5>=-0.79),"strong negative correlation",AND(C5<=-0.8,C5>=-1),"very strong negative correlation",AND(C5<=0.19,C5>0),"very weak postive correlation",AND(C5>=0.2,C5<=0.39),"weak postive correlation",AND(C5>=0.4,C5<=0.59),"moderate postive correlation",AND(C5>=0.6,C5<=0.79),"strong postive correlation",AND(C5>=0.8,C5<=1),"very weak postive correlation")} -> very weak negative correlation
A6: cpi correl | C6: {=CORREL(Walmart_Sales_raw_data!C2:C6437,Walmart_Sales_raw_data!E2:E6437)} -> -0.063810013 | D6: {=_xlfn.IFS(AND(C6>=-0.19,C6<0),"very weak negative correlation",AND(C6<=-0.2,C6>=-0.39),"weak negative correlation",AND(C6<=-0.4,C6>=-0.59),"moderate negative correlation",AND(C6<=-0.6,C6>=-0.79),"strong negative correlation",AND(C6<=-0.8,C6>=-1),"very strong negative correlation",AND(C6<=0.19,C6>0),"very weak postive correlation",AND(C6>=0.2,C6<=0.39),"weak postive correlation",AND(C6>=0.4,C6<=0.59),"moderate postive correlation",AND(C6>=0.6,C6<=0.79),"strong postive correlation",AND(C6>=0.8,C6<=1),"very weak postive correlation")} -> very weak negative correlation

Sheet Holiday_impact_by_store
A1: In this section, the impact of holidays on weekly sales by stores is investtigated. In Overall, the holiday weeks had a positive impact on weekly sales recording an 8% increase compared to non-holiday weeks. However, there were some outliers , some stores were not affected by it and some were even negatively affected by holiday weeks
A11: =list_of_stores!A1 -> Store | B11: Non_Holiday_Avg_Sales | C11: Holiday_Avg_Sales | D11: Lift_Percentage | E11: List of Stores positively impacted by holidays Click below to reveal | F11: List of Stores negatively impacted by holidays Click below to reveal
A12: =list_of_stores!A2 -> 1 | B12: =AVERAGEIFS(Walmart_Sales_raw_data!$C:$C,Walmart_Sales_raw_data!$A:$A,A12,Walmart_Sales_raw_data!$D:$D,0) -> 1546957.4 | C12: =AVERAGEIFS(Walmart_Sales_raw_data!$C:$C,Walmart_Sales_raw_data!$A:$A,A12,Walmart_Sales_raw_data!$D:$D,1) -> 1665747.7 | D12: =(C12-B12)/B12 -> 0.07678962
A13: =list_of_stores!A3 -> 2 | B13: =AVERAGEIFS(Walmart_Sales_raw_data!$C:$C,Walmart_Sales_raw_data!$A:$A,A13,Walmart_Sales_raw_data!$D:$D,0) -> 1914208.8 | C13: =AVERAGEIFS(Walmart_Sales_raw_data!$C:$C,Walmart_Sales_raw_data!$A:$A,A13,Walmart_Sales_raw_data!$D:$D,1) -> 2079266.9 | D13: =(C13-B13)/B13 -> 0.086227838
A14: =list_of_stores!A4 -> 3 | B14: =AVERAGEIFS(Walmart_Sales_raw_data!$C:$C,Walmart_Sales_raw_data!$A:$A,A14,Walmart_Sales_raw_data!$D:$D,0) -> 400064.85 | C14: =AVERAGEIFS(Walmart_Sales_raw_data!$C:$C,Walmart_Sales_raw_data!$A:$A,A14,Walmart_Sales_raw_data!$D:$D,1) -> 437811.05 | D14: =(C14-B14)/B14 -> 0.094350213
A15: =list_of_stores!A5 -> 4 | B15: =AVERAGEIFS(Walmart_Sales_raw_data!$C:$C,Walmart_Sales_raw_data!$A:$A,A15,Walmart_Sales_raw_data!$D:$D,0) -> 2083555.8 | C15: =AVERAGEIFS(Walmart_Sales_raw_data!$C:$C,Walmart_Sales_raw_data!$A:$A,A15,Walmart_Sales_raw_data!$D:$D,1) -> 2243102.6 | D15: =(C15-B15)/B15 -> 0.076574276 | E15: Store most positively impacted by holidays | F15: Store most negatively impacted by holidays
A16: =list_of_stores!A6 -> 5 | B16: =AVERAGEIFS(Walmart_Sales_raw_data!$C:$C,Walmart_Sales_raw_data!$A:$A,A16,Walmart_Sales_raw_data!$D:$D,0) -> 314892.28 | C16: =AVERAGEIFS(Walmart_Sales_raw_data!$C:$C,Walmart_Sales_raw_data!$A:$A,A16,Walmart_Sales_raw_data!$D:$D,1) -> 359501.61 | D16: =(C16-B16)/B16 -> 0.14166537
A17: =list_of_stores!A7 -> 6 | B17: =AVERAGEIFS(Walmart_Sales_raw_data!$C:$C,Walmart_Sales_raw_data!$A:$A,A17,Walmart_Sales_raw_data!$D:$D,0) -> 1555992.9 | C17: =AVERAGEIFS(Walmart_Sales_raw_data!$C:$C,Walmart_Sales_raw_data!$A:$A,A17,Walmart_Sales_raw_data!$D:$D,1) -> 1680907.9 | D17: =(C17-B17)/B17 -> 0.080279969
A18: =list_of_stores!A8 -> 7 | B18: =AVERAGEIFS(Walmart_Sales_raw_data!$C:$C,Walmart_Sales_raw_data!$A:$A,A18,Walmart_Sales_raw_data!$D:$D,0) -> 562964.45 | C18: =AVERAGEIFS(Walmart_Sales_raw_data!$C:$C,Walmart_Sales_raw_data!$A:$A,A18,Walmart_Sales_raw_data!$D:$D,1) -> 672400.27 | D18: =(C18-B18)/B18 -> 0.19439204 | E18: =_xlfn.XLOOKUP(MAX(D12:D56),D12:D56,A12:A56) -> 7 | F18: =_xlfn.XLOOKUP(MIN(D12:D56),D12:D56,A12:A56) -> 44
A19: =list_of_stores!A9 -> 8 | B19: =AVERAGEIFS(Walmart_Sales_raw_data!$C:$C,Walmart_Sales_raw_data!$A:$A,A19,Walmart_Sales_raw_data!$D:$D,0) -> 903743.4 | C19: =AVERAGEIFS(Walmart_Sales_raw_data!$C:$C,Walmart_Sales_raw_data!$A:$A,A19,Walmart_Sales_raw_data!$D:$D,1) -> 975330.86 | D19: =(C19-B19)/B19 -> 0.07921215
A20: =list_of_stores!A10 -> 9 | B20: =AVERAGEIFS(Walmart_Sales_raw_data!$C:$C,Walmart_Sales_raw_data!$A:$A,A20,Walmart_Sales_raw_data!$D:$D,0) -> 540599.33 | C20: =AVERAGEIFS(Walmart_Sales_raw_data!$C:$C,Walmart_Sales_raw_data!$A:$A,A20,Walmart_Sales_raw_data!$D:$D,1) -> 588950.82 | D20: =(C20-B20)/B20 -> 0.089440532
A21: =list_of_stores!A11 -> 10 | B21: =AVERAGEIFS(Walmart_Sales_raw_data!$C:$C,Walmart_Sales_raw_data!$A:$A,A21,Walmart_Sales_raw_data!$D:$D,0) -> 1883309.4 | C21: =AVERAGEIFS(Walmart_Sales_raw_data!$C:$C,Walmart_Sales_raw_data!$A:$A,A21,Walmart_Sales_raw_data!$D:$D,1) -> 2113755.9 | D21: =(C21-B21)/B21 -> 0.12236254
A22: =list_of_stores!A12 -> 11 | B22: =AVERAGEIFS(Walmart_Sales_raw_data!$C:$C,Walmart_Sales_raw_data!$A:$A,A22,Walmart_Sales_raw_data!$D:$D,0) -> 1349465 | C22: =AVERAGEIFS(Walmart_Sales_raw_data!$C:$C,Walmart_Sales_raw_data!$A:$A,A22,Walmart_Sales_raw_data!$D:$D,1) -> 1448394.5 | D22: =(C22-B22)/B22 -> 0.073310171
A23: =list_of_stores!A13 -> 12 | B23: =AVERAGEIFS(Walmart_Sales_raw_data!$C:$C,Walmart_Sales_raw_data!$A:$A,A23,Walmart_Sales_raw_data!$D:$D,0) -> 999291.92 | C23: =AVERAGEIFS(Walmart_Sales_raw_data!$C:$C,Walmart_Sales_raw_data!$A:$A,A23,Walmart_Sales_raw_data!$D:$D,1) -> 1138140.4 | D23: =(C23-B23)/B23 -> 0.13894688
A24: =list_of_stores!A14 -> 13 | B24: =AVERAGEIFS(Walmart_Sales_raw_data!$C:$C,Walmart_Sales_raw_data!$A:$A,A24,Walmart_Sales_raw_data!$D:$D,0) -> 1995393 | C24: =AVERAGEIFS(Walmart_Sales_raw_data!$C:$C,Walmart_Sales_raw_data!$A:$A,A24,Walmart_Sales_raw_data!$D:$D,1) -> 2113043.8 | D24: =(C24-B24)/B24 -> 0.058961233
A25: =list_of_stores!A15 -> 14 | B25: =AVERAGEIFS(Walmart_Sales_raw_data!$C:$C,Walmart_Sales_raw_data!$A:$A,A25,Walmart_Sales_raw_data!$D:$D,0) -> 2013489.3 | C25: =AVERAGEIFS(Walmart_Sales_raw_data!$C:$C,Walmart_Sales_raw_data!$A:$A,A25,Walmart_Sales_raw_data!$D:$D,1) -> 2120583 | D25: =(C25-B25)/B25 -> 0.053188096
A26: =list_of_stores!A16 -> 15 | B26: =AVERAGEIFS(Walmart_Sales_raw_data!$C:$C,Walmart_Sales_raw_data!$A:$A,A26,Walmart_Sales_raw_data!$D:$D,0) -> 617064.84 | C26: =AVERAGEIFS(Walmart_Sales_raw_data!$C:$C,Walmart_Sales_raw_data!$A:$A,A26,Walmart_Sales_raw_data!$D:$D,1) -> 706406.02 | D26: =(C26-B26)/B26 -> 0.1447841
A27: =list_of_stores!A17 -> 16 | B27: =AVERAGEIFS(Walmart_Sales_raw_data!$C:$C,Walmart_Sales_raw_data!$A:$A,A27,Walmart_Sales_raw_data!$D:$D,0) -> 515677.36 | C27: =AVERAGEIFS(Walmart_Sales_raw_data!$C:$C,Walmart_Sales_raw_data!$A:$A,A27,Walmart_Sales_raw_data!$D:$D,1) -> 566733.65 | D27: =(C27-B27)/B27 -> 0.099008197
A28: =list_of_stores!A18 -> 17 | B28: =AVERAGEIFS(Walmart_Sales_raw_data!$C:$C,Walmart_Sales_raw_data!$A:$A,A28,Walmart_Sales_raw_data!$D:$D,0) -> 887099.02 | C28: =AVERAGEIFS(Walmart_Sales_raw_data!$C:$C,Walmart_Sales_raw_data!$A:$A,A28,Walmart_Sales_raw_data!$D:$D,1) -> 979796.97 | D28: =(C28-B28)/B28 -> 0.10449561
A29: =list_of_stores!A19 -> 18 | B29: =AVERAGEIFS(Walmart_Sales_raw_data!$C:$C,Walmart_Sales_raw_data!$A:$A,A29,Walmart_Sales_raw_data!$D:$D,0) -> 1078349.7 | C29: =AVERAGEIFS(Walmart_Sales_raw_data!$C:$C,Walmart_Sales_raw_data!$A:$A,A29,Walmart_Sales_raw_data!$D:$D,1) -> 1169422.2 | D29: =(C29-B29)/B29 -> 0.084455386
A30: =list_of_stores!A20 -> 19 | B30: =AVERAGEIFS(Walmart_Sales_raw_data!$C:$C,Walmart_Sales_raw_data!$A:$A,A30,Walmart_Sales_raw_data!$D:$D,0) -> 1435070.6 | C30: =AVERAGEIFS(Walmart_Sales_raw_data!$C:$C,Walmart_Sales_raw_data!$A:$A,A30,Walmart_Sales_raw_data!$D:$D,1) -> 1577046.7 | D30: =(C30-B30)/B30 -> 0.098933177
... A56: =list_of_stores!A46 -> 45 | B56: =AVERAGEIFS(Walmart_Sales_raw_data!$C:$C,Walmart_Sales_raw_data!$A:$A,A56,Walmart_Sales_raw_data!$D:$D,0) -> 782198.53 | C56: =AVERAGEIFS(Walmart_Sales_raw_data!$C:$C,Walmart_Sales_raw_data!$A:$A,A56,Walmart_Sales_raw_data!$D:$D,1) -> 836293.71 | D56: =(C56-B56)/B56 -> 0.06915787
A57: Total | B57: =AVERAGEIFS(Walmart_Sales_raw_data!$C:$C,Walmart_Sales_raw_data!$A:$A,A57,Walmart_Sales_raw_data!$D:$D,0) -> #DIV/0! | D57: =(C57-B57)/B57 -> #DIV/0!
F74: {=_xlfn._xlws.FILTER(A12:A56,C12:C56-B12:B56>0)} -> 1 | G74: {=_xlfn._xlws.FILTER(A12:A56,C12:C56-B12:B56<0)} -> 30
F75: 2 | G75: 36
F76: 3 | G76: 37
F77: 4 | G77: 38
F78: 5 | G78: 44
F79: 6
F80: 7
F81: 8
F82: 9
F83: 10
F84: 11
F85: 12
F86: 13
F87: 14
F88: 15
F89: 16
F90: 17
...

Sheet Holiday_vs_non_holidays
A1: Holiday_Flag | B1: Average of Weekly_Sales
A2: No Holidays | B2: 1041256.4
A3: Holidays | B3: 1122887.9
A4: Grand Total | B4: 1046964.9

Sheet list_of_stores
A1: Store
A2: 1
A3: 2
A4: 3
A5: 4
A6: 5
A7: 6
A8: 7
A9: 8
A10: 9
A11: 10
A12: 11
A13: 12
... A46: 45
A47: Grand Total

Sheet sales_level
A1: Store | B1: weeklysales | C1: Sales level
A2: 1 | B2: =Walmart_Sales_raw_data!C2 -> 1643690.9 | C2: =IF(B2>=Walmart_Sales_raw_data!$C$6437,"High","low") -> High
A3: 1 | B3: =Walmart_Sales_raw_data!C3 -> 1641957.4 | C3: =IF(B3>=Walmart_Sales_raw_data!$C$6437,"High","low") -> High
A4: 1 | B4: =Walmart_Sales_raw_data!C4 -> 1611968.2 | C4: =IF(B4>=Walmart_Sales_raw_data!$C$6437,"High","low") -> High
A5: 1 | B5: =Walmart_Sales_raw_data!C5 -> 1409727.6 | C5: =IF(B5>=Walmart_Sales_raw_data!$C$6437,"High","low") -> High
A6: 1 | B6: =Walmart_Sales_raw_data!C6 -> 1554806.7 | C6: =IF(B6>=Walmart_Sales_raw_data!$C$6437,"High","low") -> High
A7: 1 | B7: =Walmart_Sales_raw_data!C7 -> 1439541.6 | C7: =IF(B7>=Walmart_Sales_raw_data!$C$6437,"High","low") -> High
A8: 1 | B8: =Walmart_Sales_raw_data!C8 -> 1472515.8 | C8: =IF(B8>=Walmart_Sales_raw_data!$C$6437,"High","low") -> High
A9: 1 | B9: =Walmart_Sales_raw_data!C9 -> 1404429.9 | C9: =IF(B9>=Walmart_Sales_raw_data!$C$6437,"High","low") -> High
A10: 1 | B10: =Walmart_Sales_raw_data!C10 -> 1594968.3 | C10: =IF(B10>=Walmart_Sales_raw_data!$C$6437,"High","low") -> High
A11: 1 | B11: =Walmart_Sales_raw_data!C11 -> 1545418.5 | C11: =IF(B11>=Walmart_Sales_raw_data!$C$6437,"High","low") -> High
A12: 1 | B12: =Walmart_Sales_raw_data!C12 -> 1466058.3 | C12: =IF(B12>=Walmart_Sales_raw_data!$C$6437,"High","low") -> High
A13: 1 | B13: =Walmart_Sales_raw_data!C13 -> 1391256.1 | C13: =IF(B13>=Walmart_Sales_raw_data!$C$6437,"High","low") -> High
... A6436: 45 | B6436: =Walmart_Sales_raw_data!C6436 -> 760281.43 | C6436: =IF(B6436>=Walmart_Sales_raw_data!$C$6437,"High","low") -> low
